<?xml version="1.0" encoding="utf-8"?>
<!-- This URDF was automatically created by SolidWorks to URDF Exporter! Originally created by Stephen Brawner (brawner@gmail.com) 
     Commit Version: 1.6.0-4-g7f85cfe  Build Version: 1.6.7995.38578
     For more information, please see http://wiki.ros.org/sw_urdf_exporter -->
<robot
  name="titatit_robot_2">
  <link
    name="base">
    <visual>
      <origin rpy="0 0 0" xyz="0 0 0"/>
      <geometry>
        <mesh filename="../meshes/body.stl" scale="1 1 1"/>
      </geometry>
            <!-- <origin rpy="0 0 0" xyz="0 0 0"/>
      <geometry>
        <box size="0.4 0.25 0.109"/>
      </geometry> -->
            <material
        name="">
        <color
          rgba="1 1 1 1" />
      </material>
    </visual>
    <collision>
      <origin rpy="0 0 0" xyz="0 0 0"/>
      <geometry>
        <box size="0.4 0.25 0.109"/>
      </geometry>
    </collision>
    <inertial>
      <origin rpy="0 0 0" xyz="0.0273 -0.000242 0.0143"/>
      <mass value="4.03"/>
      <inertia ixx="0.0185" ixy="-0.000173" ixz="-0.0102" iyy="0.0517" iyz="-2.83e-05" izz="0.0483"/>
    </inertial>
  </link>
  <link
    name="FL_hip">
     <visual>
      <origin rpy="0 0 0" xyz="0 0 0"/>
      <geometry>
        <mesh filename="../meshes/abad.stl" scale="1 1 1"/>
      </geometry>
      <!-- <origin rpy="1.5707963267948966 0 0" xyz="0 0 0"/>
      <geometry>
        <cylinder length="0.035" radius="0.039"/>
      </geometry> -->
      <material
        name="">
        <color
          rgba="1 1 1 1" />
      </material>
    </visual>
    <collision>
      <origin rpy="1.5707963267948966 0 0" xyz="0 0 0"/>
      <geometry>
        <cylinder length="0.035" radius="0.039"/>
      </geometry>
    </collision>
    <inertial>
      <origin rpy="0 0 0" xyz="-0.00392 0.015 -0.000306"/>
      <mass value="0.354"/>
      <inertia ixx="0.00019" ixy="-2.7e-05" ixz="-3.44e-07" iyy="0.000276" iyz="1.95e-06" izz="0.000233"/>
    </inertial>
  </link>
  <joint
    name="FL_hip_joint"
    type="revolute">
    <origin rpy="0 0 0" xyz="0.164 0.042 0"/>

    <parent
      link="base" />
    <child
      link="FL_hip" />
    <axis
      xyz="1 0 0" />
    <limit effort="12.0001" lower="-0.6806784082777885" upper="0.6806784082777885" velocity="30.9971"/>
  </joint>
  <link
    name="FL_thigh">
  <visual>
      <origin rpy="0 0 0" xyz="0 0 0"/>
      <geometry>
        <mesh filename="../meshes/hip.stl" scale="1 1 1"/>
      </geometry>
            <!-- <origin rpy="0 1.5707963267948966 0" xyz="0 0 -0.06"/>
      <geometry>
        <box size="0.12 0.025 0.034"/>
      </geometry> -->
      <material
        name="">
        <color
          rgba="1 1 1 1" />
      </material>
    </visual>
    <collision>
      <!-- <origin rpy="0 1.5707963267948966 0" xyz="0 0 -0.06"/>
      <geometry>
        <box size="0.12 0.025 0.034"/>
      </geometry> -->
    </collision>
    <inertial>
      <origin rpy="0 0 0" xyz="-0.00212 -0.0212 -0.0184"/>
      <mass value="0.482"/>
      <inertia ixx="0.00101" ixy="2.23e-05" ixz="-3.85e-05" iyy="0.000983" iyz="0.000199" izz="0.000347"/>
    </inertial>
  </link>
  <joint
    name="FL_thigh_joint"
    type="revolute">
    <origin rpy="0 0 0" xyz="0 0.094 0"/>
    <parent link="FL_hip"/>
    <child link="FL_thigh"/>
    <axis xyz="0 1 0"/>
    <dynamics damping="0" friction="0"/>
    <limit effort="12.0001" lower="-1.3264502315156903" upper="2.792526803190927" velocity="30.9971"/>
  </joint>
  <link
    name="FL_calf">
    <visual>
      <origin rpy="0 0 0" xyz="0 0 0"/>
      <geometry>
        <mesh filename="../meshes/knee.stl" scale="1 1 1"/>
      </geometry>
        <!-- <origin rpy="0 3.141592653589793 0" xyz="0 0 -0.091705"/>
      <geometry>
        <box size="0.016 0.016 0.18341"/>
      </geometry> -->
      <material
        name="">
        <color
          rgba="1 1 1 1" />
      </material>
    </visual>
    <collision>
      <origin rpy="0 3.141592653589793 0" xyz="0 0 -0.091705"/>
      <geometry>
        <box size="0.016 0.016 0.18341"/>
      </geometry>
    </collision>
    <!-- <collision name="FL_knee_rubber">
      <origin rpy="0 3.141592653589793 0" xyz="-0.01 0 -0.007"/>
      <geometry>
        <sphere radius="0.016"/>
      </geometry>
      <surface>
        <contact>
          <ode>
            <max_vel>0.00001</max_vel>
            <min_depth>0.0</min_depth>
          </ode>
        </contact>
      </surface>
    </collision> -->
    <inertial>
      <origin rpy="0 0 0" xyz="0.0006 -4.72e-05 -0.0893"/>
      <mass value="0.116"/>
      <inertia ixx="0.000668" ixy="3e-09" ixz="2.37e-05" iyy="0.000674" iyz="6.03e-07" izz="1.54e-05"/>
    </inertial>
  </link>
  <joint
    name="FL_calf_joint"
    type="revolute">
    <origin rpy="0 0 0" xyz="0 0 -0.12"/>
    <parent link="FL_thigh"/>
    <child link="FL_calf"/>
    <axis xyz="0 1 0"/>
    <dynamics damping="0" friction="0"/>
    <limit effort="12.0001" lower="-2.5307274153917776" upper="-0.5235987755982988" velocity="30.9971"/>
  </joint>
  <link
    name="FL_foot">
    <inertial>
      <origin
        xyz="0 0 0"
        rpy="0 0 0" />
      <mass
        value="0.004" />
      <inertia ixx="2.4e-05" ixy="0.0" ixz="0.0" iyy="2.4e-05" iyz="0.0" izz="2.4e-05"/>
    </inertial>
    <visual>
      <origin
        xyz="0 0 0"
        rpy="0 0 0" />
      <!-- <geometry>
        <mesh
          filename="../dae/FL_foot.dae" />
      </geometry> -->
      <geometry>
        <sphere radius="0.01"/>
      </geometry>
      <material
        name="">
        <color
          rgba="0.698039215686274 0.698039215686274 0.698039215686274 1" />
      </material>
    </visual>
    <collision>
      <origin rpy="0 0 0" xyz="0 0 0"/>
      <geometry>
        <sphere radius="0.02"/>
      </geometry>
    </collision>
  </link>
  <joint
    name="FL_foot_joint"
    type="fixed" dont_collapse="true">
    <origin
      xyz="0 0 -0.18341"
      rpy="0 0 0" />
    <parent
      link="FL_calf" />
    <child
      link="FL_foot" />
    <axis
      xyz="0 1 0" />
  </joint>
    <!-- <joint name="foot_joint_fl" type="fixed" dont_collapse="true">
    <origin rpy="0 0 -0.87266" xyz="0.2 0 0.0514"/>
    <parent link="FL_calf"/>
    <child link="FL_foot"/> -->
  <!-- </joint> -->
  <link
    name="FR_hip">
     <visual>
      <origin rpy="3.141592653589793 0 0" xyz="0 0 0"/>
      <geometry>
        <mesh filename="../meshes/abad.stl" scale="1 1 1"/>
      </geometry>
      <!-- <origin rpy="1.5707963267948966 0 0" xyz="0 0 0"/>
      <geometry>
        <cylinder length="0.035" radius="0.039"/>
      </geometry> -->
      <material
        name="">
        <color
          rgba="1 1 1 1" />
      </material>
    </visual>
    <collision>
      <origin rpy="1.5707963267948966 0 0" xyz="0 0 0"/>
      <geometry>
        <cylinder length="0.035" radius="0.039"/>
      </geometry>
    </collision>
    <inertial>
      <origin rpy="0 0 0" xyz="-0.00392 -0.015 -0.000306"/>
      <mass value="0.354"/>
      <inertia ixx="0.00019" ixy="2.7e-05" ixz="-3.44e-07" iyy="0.000276" iyz="-1.95e-06" izz="0.000233"/>
    </inertial>
  </link>
  <joint
    name="FR_hip_joint"
    type="revolute">
    <origin rpy="0 0 0" xyz="0.164 -0.042 0"/>
    <parent
      link="base" />
    <child
      link="FR_hip" />
    <axis
      xyz="1 0 0" />
    <limit effort="12.0001" lower="-0.6806784082777885" upper="0.6806784082777885" velocity="30.9971"/>
  </joint>
  <link
    name="FR_thigh">
   <visual>
      <origin rpy="0 0 0" xyz="0 0 0"/>
      <geometry>
        <mesh filename="../meshes/hip_mirror.stl" scale="1 1 1"/>
      </geometry>
           <!-- <origin rpy="0 1.5707963267948966 0" xyz="0 0 -0.06"/>
      <geometry>
        <box size="0.12 0.025 0.034"/>
      </geometry>  -->
      
      <material
        name="">
        <color
          rgba="1 1 1 1" />
      </material>
    </visual>
    <collision>
      <!-- <origin rpy="0 1.5707963267948966 0" xyz="0 0 -0.06"/>
      <geometry>
        <box size="0.12 0.025 0.034"/>
      </geometry> -->
    </collision>
    <inertial>
      <origin rpy="0 0 0" xyz="-0.00212 0.0212 -0.0184"/>
      <mass value="0.482"/>
      <inertia ixx="0.00101" ixy="-2.23e-05" ixz="-3.85e-05" iyy="0.000983" iyz="-0.000199" izz="0.000347"/>
    </inertial>
  </link>
  <joint
    name="FR_thigh_joint"
    type="revolute">
    <origin rpy="0 0 0" xyz="0 -0.094 0"/>
    <parent link="FR_hip"/>
    <child link="FR_thigh"/>
    <axis xyz="0 1 0"/>
    <dynamics damping="0" friction="0"/>
    <limit effort="12.0001" lower="-1.3264502315156903" upper="2.792526803190927" velocity="30.9971"/>
  </joint>
  <link
    name="FR_calf">
  <visual>
      <origin rpy="0 0 0" xyz="0 0 0"/>
      <geometry>
        <mesh filename="../meshes/knee.stl" scale="1 1 1"/>
      </geometry>
            <!-- <origin rpy="0 3.141592653589793 0" xyz="0 0 -0.091705"/>
      <geometry>
        <box size="0.016 0.016 0.18341"/>
      </geometry> -->
      <material
        name="">
        <color
          rgba="1 1 1 1" />
      </material>
    </visual>
    <collision>
      <origin rpy="0 3.141592653589793 0" xyz="0 0 -0.091705"/>
      <geometry>
        <box size="0.016 0.016 0.18341"/>
      </geometry>
    </collision>
    <!-- <collision name="FR_knee_rubber">
      <origin rpy="0 3.141592653589793 0" xyz="-0.01 0 -0.007"/>
      <geometry>
        <sphere radius="0.016"/>
      </geometry>
      <surface>
        <contact>
          <ode>
            <max_vel>0.00001</max_vel>
            <min_depth>0.0</min_depth>
          </ode>
        </contact>
      </surface>
    </collision> -->
    <inertial>
      <origin rpy="0 0 0" xyz="0.0006 -4.72e-05 -0.0893"/>
      <mass value="0.116"/>
      <inertia ixx="0.000668" ixy="3e-09" ixz="2.37e-05" iyy="0.000674" iyz="6.03e-07" izz="1.54e-05"/>
    </inertial>
  </link>
  <joint
    name="FR_calf_joint"
    type="revolute">
    <origin rpy="0 0 0" xyz="0 0 -0.12"/>
    <parent link="FR_thigh"/>
    <child link="FR_calf"/>
    <axis xyz="0 1 0"/>
    <dynamics damping="0" friction="0"/>
    <limit effort="12.0001" lower="-2.5307274153917776" upper="-0.5235987755982988" velocity="30.9971"/>
  </joint>
  <link
    name="FR_foot">
    <inertial>
      <origin
        xyz="-3.1517325252417E-07 2.84212870238498E-06 -0.000955954818488869"
        rpy="0 0 0" />
      <mass
        value="0.004" />
      <inertia ixx="2.4e-05" ixy="0.0" ixz="0.0" iyy="2.4e-05" iyz="0.0" izz="2.4e-05"/>
    </inertial>
    <visual>
      <origin
        xyz="0 0 0"
        rpy="0 0 0" />
      <!-- <geometry>
        <mesh
          filename="../dae/FR_foot.dae" />
      </geometry> -->
      <geometry>
        <sphere radius="0.01"/>
      </geometry>
      <material
        name="">
        <color
          rgba="0.698039215686274 0.698039215686274 0.698039215686274 1" />
      </material>
    </visual>
    <collision>
      <origin rpy="0 0 0" xyz="0 0 0"/>
      <geometry>
        <sphere radius="0.02"/>
      </geometry>
    </collision>
  </link>
  <joint
    name="FR_foot_joint"
    type="fixed" dont_collapse="true">
    <origin
      xyz="0 0 -0.18341"
      rpy="0 0 0" />
    <parent
      link="FR_calf" />
    <child
      link="FR_foot" />
    <axis
      xyz="0 1 0" />
  </joint>
      <!-- <joint name="foot_joint_fr" type="fixed" dont_collapse="true">
    <origin rpy="0 0 -0.87266" xyz="0.2 0 0.0514"/>
    <parent link="FR_calf"/>
    <child link="FR_foot"/>
  </joint> -->
  <link
    name="RL_hip">
  <visual>
      <origin rpy="0 3.141592653589793 0" xyz="0 0 0"/>
      <geometry>
        <mesh filename="../meshes/abad.stl" scale="1 1 1"/>
      </geometry>
      <!-- <origin rpy="1.5707963267948966 0 0" xyz="0 0 0"/>
      <geometry>
        <cylinder length="0.035" radius="0.039"/>
      </geometry> -->
      <material
        name="">
        <color
          rgba="1 1 1 1" />
      </material>
    </visual>
    <collision>
      <origin rpy="1.5707963267948966 0 0" xyz="0 0 0"/>
      <geometry>
        <cylinder length="0.035" radius="0.039"/>
      </geometry>
    </collision>
    <inertial>
      <origin rpy="0 0 0" xyz="0.00392 0.015 -0.000306"/>
      <mass value="0.354"/>
      <inertia ixx="0.00019" ixy="2.7e-05" ixz="3.44e-07" iyy="0.000276" iyz="1.95e-06" izz="0.000233"/>
    </inertial>
  </link>
  <joint
    name="RL_hip_joint"
    type="revolute">
    <origin rpy="0 0 0" xyz="-0.164 0.042 0"/>

    <parent link="base"/>
    <child link="RL_hip"/>
    <axis xyz="1 0 0"/>
    <dynamics damping="0" friction="0"/>
    <limit effort="12.0001" lower="-0.6806784082777885" upper="0.6806784082777885" velocity="30.9971"/>
  </joint>
  <link
    name="RL_thigh">
    <visual>
      <origin rpy="0 0 0" xyz="0 0 0"/>
      <geometry>
        <mesh filename="../meshes/hip.stl" scale="1 1 1"/>
      </geometry>
            <!-- <origin rpy="0 1.5707963267948966 0" xyz="0 0 -0.06"/>
      <geometry>
        <box size="0.12 0.025 0.034"/>
      </geometry> -->
      <material
        name="">
        <color
          rgba="1 1 1 1" />
      </material>
    </visual>
    <collision>
      <!-- <origin rpy="0 1.5707963267948966 0" xyz="0 0 -0.06"/>
      <geometry>
        <box size="0.12 0.025 0.034"/>
      </geometry> -->
    </collision>
    <inertial>
      <origin rpy="0 0 0" xyz="-0.00212 -0.0212 -0.0184"/>
      <mass value="0.482"/>
      <inertia ixx="0.00101" ixy="2.23e-05" ixz="-3.85e-05" iyy="0.000983" iyz="0.000199" izz="0.000347"/>
    </inertial>
  </link>
  <joint
    name="RL_thigh_joint"
    type="revolute">
    <origin rpy="0 0 0" xyz="0 0.094 0"/>
    <parent link="RL_hip"/>
    <child link="RL_thigh"/>
    <axis xyz="0 1 0"/>
    <dynamics damping="0" friction="0"/>
    <!-- <limit effort="100" lower="-1.0471975512" upper="4.18879020479" velocity="28.6"/> -->
    <limit effort="12.0001" lower="-0.9773843811168246" upper="3.141592653589793" velocity="30.9971"/>
  </joint>
  <link
    name="RL_calf">
  <visual>
      <origin rpy="0 0 0" xyz="0 0 0"/>
      <geometry>
        <mesh filename="../meshes/knee.stl" scale="1 1 1"/>
      </geometry>
            <!-- <origin rpy="0 3.141592653589793 0" xyz="0 0 -0.091705"/>
      <geometry>
        <box size="0.016 0.016 0.18341"/>
      </geometry> -->
      <material
        name="">
        <color
          rgba="1 1 1 1" />
      </material>
    </visual>
    <collision>
      <origin rpy="0 3.141592653589793 0" xyz="0 0 -0.091705"/>
      <geometry>
        <box size="0.016 0.016 0.18341"/>
      </geometry>
    </collision>
    <!-- <collision name="RL_knee_rubber">
      <origin rpy="0 3.141592653589793 0" xyz="-0.01 0 -0.007"/>
      <geometry>
        <sphere radius="0.016"/>
      </geometry>
      <surface>
        <contact>
          <ode>
            <max_vel>0.00001</max_vel>
            <min_depth>0.0</min_depth>
          </ode>
        </contact>
      </surface>
    </collision> -->
    <inertial>
      <origin rpy="0 0 0" xyz="0.0006 -4.72e-05 -0.0893"/>
      <mass value="0.116"/>
      <inertia ixx="0.000668" ixy="3e-09" ixz="2.37e-05" iyy="0.000674" iyz="6.03e-07" izz="1.54e-05"/>
    </inertial>
  </link>
  <joint
    name="RL_calf_joint"
    type="revolute">
    <origin rpy="0 0 0" xyz="0 0 -0.12"/>
    <parent link="RL_thigh"/>
    <child link="RL_calf"/>
    <axis xyz="0 1 0"/>
    <dynamics damping="0" friction="0"/>
    <!-- <limit effort="100" lower="-2.69653369433" upper="-0.916297857297" velocity="28.6"/> -->
    <limit effort="12.0001" lower="-2.5307274153917776" upper="-0.5235987755982988" velocity="30.9971"/>
  </joint>
  <link
    name="RL_foot">
    <inertial>
      <origin
        xyz="3.15173430132099E-07 -2.84212862960986E-06 -0.000955954818523563"
        rpy="0 0 0" />
      <mass
        value="0.004" />
      <inertia ixx="2.4e-05" ixy="0.0" ixz="0.0" iyy="2.4e-05" iyz="0.0" izz="2.4e-05"/>
    </inertial>
    <visual>
      <origin
        xyz="0 0 0"
        rpy="0 0 0" />
      <!-- <geometry>
        <mesh
          filename="../dae/RL_foot.dae" />
      </geometry> -->
      <geometry>
        <sphere radius="0.01"/>
      </geometry>
      <material
        name="">
        <color
          rgba="0.698039215686274 0.698039215686274 0.698039215686274 1" />
      </material>
    </visual>
    <collision>
      <origin rpy="0 0 0" xyz="0 0 0"/>
      <geometry>
        <sphere radius="0.02"/>
      </geometry>
    </collision>
  </link>
  <joint
    name="RL_foot_joint"
    type="fixed" dont_collapse="true">
    <origin rpy="0 1 0" xyz="0 0 -0.18341"/>
    <parent link="RL_calf"/>
    <child link="RL_foot"/>
  </joint>
      <!-- <joint name="foot_joint_rl" type="fixed" dont_collapse="true">
    <origin rpy="0 0 -0.87266" xyz="0.2 0 0.0514"/>
    <parent link="RL_calf"/>
    <child link="RL_foot"/>
  </joint> -->
  <link
    name="RR_hip">
   <visual>
      <origin rpy="3.141592653589793 3.141592653589793 0" xyz="0 0 0"/>
      <geometry>
        <mesh filename="../meshes/abad.stl" scale="1 1 1"/>
      </geometry>
           <!-- <origin rpy="1.5707963267948966 0 0" xyz="0 0 0"/>
      <geometry>
        <cylinder length="0.035" radius="0.039"/>
      </geometry> -->
      <material
        name="">
        <color
          rgba="1 1 1 1" />
      </material>
    </visual>
    <collision>
      <origin rpy="1.5707963267948966 0 0" xyz="0 0 0"/>
      <geometry>
        <cylinder length="0.035" radius="0.039"/>
      </geometry>
    </collision>
    <inertial>
      <origin rpy="0 0 0" xyz="0.00392 -0.015 -0.000306"/>
      <mass value="0.354"/>
      <inertia ixx="0.00019" ixy="-2.7e-05" ixz="3.44e-07" iyy="0.000276" iyz="-1.95e-06" izz="0.000233"/>
    </inertial>
  </link>
  <joint
    name="RR_hip_joint"
    type="revolute">
    <origin rpy="0 0 0" xyz="-0.164 -0.042 0"/>

    <parent link="base"/>
    <child link="RR_hip"/>
    <axis xyz="1 0 0"/>
    <dynamics damping="0" friction="0"/>
    <limit effort="12.0001" lower="-0.6806784082777885" upper="0.6806784082777885" velocity="30.9971"/>
  </joint>
  <link
    name="RR_thigh">
  <visual>
      <origin rpy="0 0 0" xyz="0 0 0"/>
      <geometry>
        <mesh filename="../meshes/hip_mirror.stl" scale="1 1 1"/>
      </geometry>
            <!-- <origin rpy="0 1.5707963267948966 0" xyz="0 0 -0.06"/>
      <geometry>
        <box size="0.12 0.025 0.034"/>
      </geometry> -->
      <material
        name="">
        <color
          rgba="1 1 1 1" />
      </material>
    </visual>
    <collision>
      <!-- <origin rpy="0 1.5707963267948966 0" xyz="0 0 -0.06"/>
      <geometry>
        <box size="0.12 0.025 0.034"/>
      </geometry> -->
    </collision>
    <inertial>
      <origin rpy="0 0 0" xyz="-0.00212 0.0212 -0.0184"/>
      <mass value="0.482"/>
      <inertia ixx="0.00101" ixy="-2.23e-05" ixz="-3.85e-05" iyy="0.000983" iyz="-0.000199" izz="0.000347"/>
    </inertial>
  </link>
  <joint
    name="RR_thigh_joint"
    type="revolute">
    <origin rpy="0 0 0" xyz="0 -0.094 0"/>
    <parent link="RR_hip"/>
    <child link="RR_thigh"/>
    <axis xyz="0 1 0"/>
    <dynamics damping="0" friction="0"/>
    <!-- <limit effort="100" lower="-1.0471975512" upper="4.18879020479" velocity="28.6"/> -->
    <limit effort="12.0001" lower="-0.9773843811168246" upper="3.141592653589793" velocity="30.9971"/>
  </joint>
  <link
    name="RR_calf">
   <visual>
      <origin rpy="0 0 0" xyz="0 0 0"/>
      <geometry>
        <mesh filename="../meshes/knee.stl" scale="1 1 1"/>
      </geometry>
            <!-- <origin rpy="0 3.141592653589793 0" xyz="0 0 -0.091705"/>
      <geometry>
        <box size="0.016 0.016 0.18341"/>
      </geometry> -->
      <material
        name="">
        <color
          rgba="1 1 1 1" />
      </material>
    </visual>
    <collision>
      <origin rpy="0 3.141592653589793 0" xyz="0 0 -0.091705"/>
      <geometry>
        <box size="0.016 0.016 0.18341"/>
      </geometry>
    </collision>
    <!-- <collision name="RR_knee_rubber">
      <origin rpy="0 3.141592653589793 0" xyz="-0.01 0 -0.007"/>
      <geometry>
        <sphere radius="0.016"/>
      </geometry>
      <surface>
        <contact>
          <ode>
            <max_vel>0.00001</max_vel>
            <min_depth>0.0</min_depth>
          </ode>
        </contact>
      </surface>
    </collision> -->
    <inertial>
      <origin rpy="0 0 0" xyz="0.0006 -4.72e-05 -0.0893"/>
      <mass value="0.116"/>
      <inertia ixx="0.000668" ixy="3e-09" ixz="2.37e-05" iyy="0.000674" iyz="6.03e-07" izz="1.54e-05"/>
    </inertial>
  </link>
  <joint
    name="RR_calf_joint"
    type="revolute">
    <origin rpy="0 0 0" xyz="0 0 -0.12"/>
    <parent link="RR_thigh"/>
    <child link="RR_calf"/>
    <axis xyz="0 1 0"/>
    <dynamics damping="0" friction="0"/>
    <!-- <limit effort="100" lower="-2.69653369433" upper="-0.916297857297" velocity="28.6"/> -->
    <limit effort="12.0001" lower="-2.5307274153917776" upper="-0.5235987755982988" velocity="30.9971"/>
  </joint>
  <link
    name="RR_foot">
    <inertial>
      <origin
        xyz="0 0 0"
        rpy="0 0 0" />
      <mass
        value="0.004" />
      <inertia ixx="2.4e-05" ixy="0.0" ixz="0.0" iyy="2.4e-05" iyz="0.0" izz="2.4e-05"/>
    </inertial>
    <visual>
      <origin
        xyz="0 0 0"
        rpy="0 0 0" />
      <!-- <geometry>
        <mesh
          filename="../dae/RR_foot.dae" />
      </geometry> -->
      <geometry>
        <sphere radius="0.01"/>
      </geometry>
      <material
        name="">
        <color
          rgba="0.698039215686274 0.698039215686274 0.698039215686274 1" />
      </material>
    </visual>
    <collision>
      <origin rpy="0 0 0" xyz="0 0 0"/>
      <geometry>
        <sphere radius="0.02"/>
      </geometry>
    </collision>
  </link>
  <joint
    name="RR_foot_joint"
    type="fixed" dont_collapse="true">
    <origin rpy="0 1 0" xyz="0 0 -0.18341"/>
    <parent link="RR_calf"/>
    <child link="RR_foot"/>
  </joint>
  <link
    name="FL_battery">
 
  </link>
  <joint
    name="battery_joint_fl"
    type="fixed">
    <origin
      xyz="0.09775 0.07 0"
      rpy="0 0 0" />
    <parent
      link="base" />
    <child
      link="FL_battery" />
    <axis
      xyz="0 0 0" />
  </joint>
  <link
    name="FR_battery">
 
  </link>
  <joint
    name="battery_joint_fr"
    type="fixed">
    <origin
      xyz="0.09775 -0.07 0"
      rpy="0 0 0" />
    <parent
      link="base" />
    <child
      link="FR_battery" />
    <axis
      xyz="0 0 0" />
  </joint>
  <link
    name="RL_battery">
   
  </link>
  <joint
    name="battery_joint_rl"
    type="fixed">
    <origin
      xyz="-0.09775 0.07 0"
      rpy="0 0 0" />
    <parent
      link="base" />
    <child
      link="RL_battery" />
    <axis
      xyz="0 0 0" />
  </joint>
  <link
    name="RR_battery">
  
  </link>
  <joint
    name="battery_joint_rr"
    type="fixed">
    <origin
      xyz="-0.09775 -0.07 0"
      rpy="0 0 0" />
    <parent
      link="base" />
    <child
      link="RR_battery" />
    <axis
      xyz="0 0 0" />
  </joint>
</robot>